Workbook

Sheet Overview
A1: Allegheny County Sheriff Sale — Monday, November 2, 2026
A2: Source: November-Sale-List-Updated-10-22.pdf (printed 10/22/2026 2:51:38PM). Updated Wed Oct 28, 2026 4:31 AM.
A4: OK to Sell | B4: 105 | C4: Sum of opening bids: $2,248,676
A5: Almost Ready (needs only 3129.3 / verify) | B5: 17 | C5: Sum of opening bids: $492,954
A6: Residential cases still active but not ready | B6: 156
A7: All cases on the Sheriff's list | B7: 430
A9: Changes since the last update (2026-10-26 04:31)
A10: No changes to OK to Sell or Almost Ready.
A12: Update log
A13: Updated | B13: OK to Sell | C13: Source file | D13: Almost Ready
A14: 2026-10-25 22:15 | B14: 105 | C14: November-Sale-List-Updated-10-22.pdf (printed 10/22/2026 2:51:38PM) | D14: 17
A15: 2026-10-26 04:31 | B15: 105 | C15: November-Sale-List-Updated-10-22.pdf (printed 10/22/2026 2:51:38PM) | D15: 17
A16: 2026-10-28 04:31 | B16: 105 | C16: November-Sale-List-Updated-10-22.pdf (printed 10/22/2026 2:51:38PM) | D16: 17
A18: How to use: type only in the yellow YOUR ENTRY columns on OK to Sell / Almost Ready (assessed value fills in the transfer-tax estimate). Every update keeps what you typed, matched by Sale ID. The Sheriff finalizes the list the morning of the sale — check the morning-of list before bidding. Not legal advice; see Glossary.

Sheet OK to Sell
A1: OK to Sell — Mon Nov 2
A2: Active residential cases with the Sheriff's OK box checked and nothing outstanding except possibly Rule 3129.3. Status can still change before the sale.
A4: Sale ID | B4: Case # | C4: Property address | D4: City | E4: ZIP | F4: Municipality | G4: Parcel ID(s) | H4: County parcel ID (portal format) | I4: Property type | J4: Sale category | K4: Owner type | L4: Defendant / owner | M4: Plaintiff | N4: Plaintiff attorney | O4: Cost & Tax bid | P4: Free & clear min bid | Q4: Opening bid to watch | R4: Reassessed damages (judgment) | S4: Boxes Svs · 3129.2 · 3129.3 · OK | T4: Readiness note | U4: Flags / title & bidding risks | V4: Sheriff comments (verbatim) | W4: Transfer tax municipality | X4: Transfer tax rate (total) | Y4: YOUR ENTRY: Assessed value | Z4: Est. transfer tax on sheriff deed | AA4: YOUR ENTRY: Max bid | AB4: YOUR ENTRY: My notes | AC4: YOUR ENTRY: Sold for | AD4: YOUR ENTRY: Bidder # | AE4: First listed here
A5: 97NOV26 | B5: GD-21-000668 | C5: 215 Union Avenue | D5: Pittsburgh | E5: 15202 | F5: Avalon | G5: 215-P-333 | H5: 0215-P-00333-0000-00 | I5: Residential / unspecified | J5: Tax lien (Sci Fa sur tax lien) | K5: Individual | L5: Seth, Robert A. | M5: Borough of Avalon | N5: GOEHRING RUTTER & BOEHM | O5: 21673.25 | Q5: 21673.25 | S5: ✔ ✔ – ✔ | T5: Sheriff OK box checked | V5: OK TO SELL 11/2/26 | W5: Avalon Boro | X5: =IFERROR(VLOOKUP(W5,'Transfer Tax'!$A$14:$H$400,8,FALSE),"") | Z5: =IF(OR(Y5="",X5=""),"",Y5*'Transfer Tax'!$B$6*X5) | AE5: 2026-10-25
A6: 101NOV26 | B6: GD-25-006792 | C6: 925 Jackman Ave | D6: Pittsburgh | E6: 15202 | F6: Avalon | G6: 160-J-93 | H6: 0160-J-00093-0000-00 | I6: Residential / unspecified | J6: Tax lien (Sci Fa sur tax lien) | K6: Individual | L6: Hellerman, Allen B. | M6: Borough of Avalon | N6: GOEHRING RUTTER & BOEHM | O6: 136212.1 | Q6: 136212.1 | S6: ✔ ✔ – ✔ | T6: Sheriff OK box checked | V6: OK TO SELL 11/2/26 | W6: Avalon Boro | X6: =IFERROR(VLOOKUP(W6,'Transfer Tax'!$A$14:$H$400,8,FALSE),"") | Z6: =IF(OR(Y6="",X6=""),"",Y6*'Transfer Tax'!$B$6*X6) | AE6: 2026-10-25
A7: 9SEP26 | B7: MG-26-000258 | C7: 929 Sedalia Avenue | D7: Pittsburgh | E7: 15202 | F7: Avalon | G7: 215-J-249 | H7: 0215-J-00249-0000-00 | I7: Residential / unspecified | J7: Mortgage foreclosure | K7: Individual | L7: Henry, Autumn M. | M7: Lakeview Loan Servicing LLC | N7: KML LAW GROUP | O7: 2063.72 | Q7: 2063.72 | R7: 94376.8 | S7: ✔ ✔ ✔ ✔ | T7: Sheriff OK box checked | V7: OK TO SELL 11-2-26 O/C TO REASSESS DAMAGES TO $94,376.80 | W7: Avalon Boro | X7: =IFERROR(VLOOKUP(W7,'Transfer Tax'!$A$14:$H$400,8,FALSE),"") | Z7: =IF(OR(Y7="",X7=""),"",Y7*'Transfer Tax'!$B$6*X7) | AE7: 2026-10-25
A8: 2NOV26 | B8: GD-23-010808 | C8: 2670 Broad Street | D8: Bethel Park | E8: 15102 | F8: Bethel Park | G8: 476-C-23 | H8: 0476-C-00023-0000-00 | I8: Residential / unspecified | J8: Tax lien (Sci Fa sur tax lien) | K8: Individual | L8: McGuire, Patrick T | M8: Bethel Park School District | N8: WEISS BURKARDT KRAMER LLC | O8: 40854.87 | Q8: 40854.87 | S8: ✔ ✔ – ✔ | T8: Sheriff OK box checked | V8: OK TO SELL 11/2/26 | W8: Bethel Park Municipality | X8: =IFERROR(VLOOKUP(W8,'Transfer Tax'!$A$14:$H$400,8,FALSE),"") | Z8: =IF(OR(Y8="",X8=""),"",Y8*'Transfer Tax'!$B$6*X8) | AE8: 2026-10-25
A9: 8NOV26 | B9: MG-22-000715 | C9: 442 Limestone Drive | D9: Bethel Park | E9: 15102 | F9: Bethel Park | G9: 774-E-20 | H9: 0774-E-00020-0000-00 | I9: Residential / unspecified | J9: Mortgage foreclosure | K9: Individual | L9: Lucido, Erin E | M9: U.S. Bank Trust National Association | N9: HLADIK ONORATO AND FEDERMAN LLP | O9: 14091.23 | Q9: 14091.23 | R9: 324967.67 | S9: ✔ ✔ – ✔ | T9: Sheriff OK box checked | V9: OK TO SELL 11/2/26 RCVD O/C TO REASSESS DAMAGES $324,967.67 | W9: Bethel Park Municipality | X9: =IFERROR(VLOOKUP(W9,'Transfer Tax'!$A$14:$H$400,8,FALSE),"") | Z9: =IF(OR(Y9="",X9=""),"",Y9*'Transfer Tax'!$B$6*X9) | AE9: 2026-10-25
A10: 50OCT26 | B10: GD-25-003997 | C10: 5919 Dorlyn Drive | D10: Bethel Park | E10: 15102 | F10: Bethel Park | G10: 773-A-132 | H10: 0773-A-00132-0000-00 | I10: Residential / unspecified | J10: Tax lien (Sci Fa sur tax lien) | K10: Individual | L10: Slifer, Richel | M10: County of Allegheny | N10: GOEHRING RUTTER & BOEHM | O10: 38158.07 | Q10: 38158.07 | S10: ✔ ✔ ✔ ✔ | T10: Sheriff OK box checked | V10: OK TO SELL 11-2-26 | W10: Bethel Park Municipality | X10: =IFERROR(VLOOKUP(W10,'Transfer Tax'!$A$14:$H$400,8,FALSE),"") | Z10: =IF(OR(Y10="",X10=""),"",Y10*'Transfer Tax'!$B$6*X10) | AE10: 2026-10-25
A11: 64NOV26 | B11: MG-26-000083 | C11: 213 Comrie Avenue | D11: Braddock | E11: 15104 | F11: Braddock | G11: 236-M-311 | H11: 0236-M-00311-0000-00 | I11: Residential / unspecified | J11: Mortgage foreclosure | K11: Individual | L11: Strozier, Erica R. | M11: Pennsylvania Housing Finance Agency | N11: PURCELL KRUG & HALLER | O11: 2108.6 | Q11: 2108.6 | S11: ✔ ✔ – ✔ | T11: Sheriff OK box checked | V11: OK TO SELL 11/2/26 | W11: Braddock Boro | X11: =IFERROR(VLOOKUP(W11,'Transfer Tax'!$A$14:$H$400,8,FALSE),"") | Z11: =IF(OR(Y11="",X11=""),"",Y11*'Transfer Tax'!$B$6*X11) | AE11: 2026-10-25
A12: 67MAR26 | B12: MG-25-000393 | C12: 125 Olancha Avenue | D12: Pittsburgh | E12: 15227 | F12: Brentwood | G12: 188-F-198 | H12: 0188-F-00198-0000-00 | I12: Residential / unspecified | J12: Mortgage foreclosure | K12: Individual | L12: Lucas, Christina Kathryn | M12: Lakeview Loan Servicing LLC | N12: HLADIK ONORATO AND FEDERMAN LLP | O12: 6387.14 | Q12: 6387.14 | S12: ✔ ✔ ✔ ✔ | T12: Sheriff OK box checked | V12: OK TO SELL 11-2-26 | W12: Brentwood Boro | X12: =IFERROR(VLOOKUP(W12,'Transfer Tax'!$A$14:$H$400,8,FALSE),"") | Z12: =IF(OR(Y12="",X12=""),"",Y12*'Transfer Tax'!$B$6*X12) | AE12: 2026-10-25
A13: 2NOV24 | B13: GD-23-014272 | C13: 61 Bellanca Avenue | D13: Pittsburgh | E13: 15227 | F13: Brentwood | G13: 137-E-315 | H13: 0137-E-00315-0000-00 | I13: Residential / unspecified | J13: Tax lien (Sci Fa sur tax lien) | K13: Individual | L13: Riland, Laura J | M13: Brentwood Borough School District | N13: TUCKER ARENSBURG PC | O13: 66430.88 | P13: 14000 | Q13: 14000 | R13: 38493.85 | S13: ✔ ✔ ✔ ✔ | T13: Sheriff OK box checked | U13: Free & clear court order, min bid $14,000.00 Bankruptcy history: 2 filing(s) | V13: OK TO SELL 11-2-26 F/C O/C FOR A MIN BID OF $14,000.00 CHP 13 BK FILED ON 10-31-24 CN-24-22661-GLT BKD RCVD 3-7-25 CHP 13 BK RCVD ON 4-25-25 CN-25-21038 -GLT BKD RCVD 9-18-25 O/C RO REASSESS DAMAGES TO $38,493.85 7-21-26 O/C RO REASSESS DAMAGES TO $35,235.20 4-22-26 O/C RO REASSESS DAMAGES TO $29,124.44 10-14-25 O/C TO REASSESS DAMAGES TO $23,920.08 3-7-25 | W13: Brentwood Boro | X13: =IFERROR(VLOOKUP(W13,'Transfer Tax'!$A$14:$H$400,8,FALSE),"") | Z13: =IF(OR(Y13="",X13=""),"",Y13*'Transfer Tax'!$B$6*X13) | AE13: 2026-10-25
A14: 95NOV26 | B14: GD-24-011416 | C14: 1061 Bank Street | D14: Bridgeville | E14: 15017 | F14: Bridgeville | G14: 322-G-230 | H14: 0322-G-00230-0000-00 | I14: Residential / unspecified | J14: Tax lien (Sci Fa sur tax lien) | K14: Individual | L14: Cawley, Matthew | M14: BOROUGH OF BRIDGEVILLE | N14: GOEHRING RUTTER & BOEHM | O14: 24361.38 | Q14: 24361.38 | S14: ✔ ✔ – ✔ | T14: Sheriff OK box checked | V14: OK TO SELL 11/2/26 | W14: Bridgeville Boro | X14: =IFERROR(VLOOKUP(W14,'Transfer Tax'!$A$14:$H$400,8,FALSE),"") | Z14: =IF(OR(Y14="",X14=""),"",Y14*'Transfer Tax'!$B$6*X14) | AE14: 2026-10-25
A15: 104NOV26 | B15: GD-22-007750 | C15: 741 Bluff Street | D15: Bridgeville | E15: 15017 | F15: Bridgeville | G15: 255-L-228 | H15: 0255-L-00228-0000-00 | I15: Residential / unspecified | J15: Tax lien (Sci Fa sur tax lien) | K15: Individual | L15: Hersh, Jamison | M15: BRIDGEVILLE BOROUGH | N15: GOEHRING RUTTER & BOEHM | O15: 17246.19 | Q15: 17246.19 | S15: ✔ ✔ – ✔ | T15: Sheriff OK box checked | V15: OK TO SELL 11/2/26 | W15: Bridgeville Boro | X15: =IFERROR(VLOOKUP(W15,'Transfer Tax'!$A$14:$H$400,8,FALSE),"") | Z15: =IF(OR(Y15="",X15=""),"",Y15*'Transfer Tax'!$B$6*X15) | AE15: 2026-10-25
A16: 49NOV26 | B16: MG-26-000215 | C16: 333 Thomas St | D16: Carnegie | E16: 15106 | F16: Carnegie | G16: 104-R-236 | H16: 0104-R-00236-0000-00 | I16: Residential / unspecified | J16: Mortgage foreclosure | K16: Individual | L16: Augustin, Mario Dean | M16: New American Funding LLC | N16: FEIN SUCH KAHN & SHEPARD | O16: 3718.93 | Q16: 3718.93 | S16: ✔ ✔ – ✔ | T16: Sheriff OK box checked | V16: OK TO SELL 11/2/26 | W16: Carnegie Boro | X16: =IFERROR(VLOOKUP(W16,'Transfer Tax'!$A$14:$H$400,8,FALSE),"") | Z16: =IF(OR(Y16="",X16=""),"",Y16*'Transfer Tax'!$B$6*X16) | AE16: 2026-10-25
A17: 98SEP26 | B17: MG-25-001016 | C17: 204 Saxonwald Lane | D17: Pittsburgh | E17: 15234 | F17: Castle Shannon | G17: 190-P-208-6 | H17: search by address | I17: Condominium | J17: Mortgage foreclosure | K17: Individual | L17: Novelli, Ryan | M17: Citizens Bank N.A. | N17: BROCK & SCOTT PLLC | O17: 2430.86 | Q17: 2430.86 | S17: ✔ ✔ ✔ ✔ | T17: Sheriff OK box checked | V17: OK TO SELL 11-2-26 | W17: Castle Shannon Boro | X17: =IFERROR(VLOOKUP(W17,'Transfer Tax'!$A$14:$H$400,8,FALSE),"") | Z17: =IF(OR(Y17="",X17=""),"",Y17*'Transfer Tax'!$B$6*X17) | AE17: 2026-10-25
A18: 113JUL26 | B18: GD-24-009514 | C18: 1102 Gary Ave | D18: Clairton | E18: 15025 | F18: Clairton | G18: 879-J-111 | H18: 0879-J-00111-0000-00 | I18: Residential / unspecified | J18: Tax lien (Sci Fa sur tax lien) | K18: Individual | L18: NIKLAS JR, DAVID A. | M18: County of Allegheny | N18: GOEHRING RUTTER & BOEHM | O18: 27435.33 | P18: 7600 | Q18: 7600 | S18: ✔ ✔ ✔ ✔ | T18: Sheriff OK box checked | U18: Free & clear court order, min bid $7,600.00 | V18: OK TO SELL 11-2-26 F/C O/C FOR A MIN BID OF $7,600.00 | W18: Clairton City | X18: =IFERROR(VLOOKUP(W18,'Transfer Tax'!$A$14:$H$400,8,FALSE),"") | Z18: =IF(OR(Y18="",X18=""),"",Y18*'Transfer Tax'!$B$6*X18) | AE18: 2026-10-25
A19: 22OCT26 | B19: MG-24-000540 | C19: 100 Scott Way | D19: Carnegie | E19: 15106 | F19: Collier | G19: 147-F-34 | H19: 0147-F-00034-0000-00 | I19: Residential / unspecified | J19: Mortgage foreclosure | K19: Individual | L19: Mulligan, Patrick J. | M19: Midfirst Bank | N19: KML LAW GROUP | O19: 26281.37 | Q19: 26281.37 | S19: ✔ ✔ ✔ ✔ | T19: Sheriff OK box checked | V19: OK TO SELL 11-2-26 | W19: Collier Twp | X19: =IFERROR(VLOOKUP(W19,'Transfer Tax'!$A$14:$H$400,8,FALSE),"") | Z19: =IF(OR(Y19="",X19=""),"",Y19*'Transfer Tax'!$B$6*X19) | AE19: 2026-10-25
A20: 145NOV26 | B20: GD-25-013374 | C20: 30 Elmwood St | D20: Pittsburgh | E20: 15205 | F20: Crafton | G20: 39-B-282 | H20: 0039-B-00282-0000-00 | I20: Residential / unspecified | J20: Tax lien (Sci Fa sur tax lien) | K20: Individual | L20: Corcoran, Gloria D. | M20: Borough of Crafton | N20: GOEHRING RUTTER & BOEHM | O20: 57841.47 | Q20: 57841.47 | S20: ✔ ✔ – ✔ | T20: Sheriff OK box checked | V20: OK TO SELL 11/2/26 | W20: Crafton Boro | X20: =IFERROR(VLOOKUP(W20,'Transfer Tax'!$A$14:$H$400,8,FALSE),"") | Z20: =IF(OR(Y20="",X20=""),"",Y20*'Transfer Tax'!$B$6*X20) | AE20: 2026-10-25
A21: 134NOV26 | B21: MG-26-000008 | C21: 90 Dinsmore Avenue | D21: Pittsburgh | E21: 15205 | F21: Crafton | G21: 40-N-121 | H21: 0040-N-00121-0000-00 | I21: Residential / unspecified | J21: Mortgage foreclosure | K21: Individual | L21: Lukaszewicz, Debora | M21: Wells Fargo Bank N.A. | N21: BROCK & SCOTT PLLC | O21: 4982.21 | Q21: 4982.21 | S21: ✔ ✔ – ✔ | T21: Sheriff OK box checked | V21: OK TO SELL 11/2/26 | W21: Crafton Boro | X21: =IFERROR(VLOOKUP(W21,'Transfer Tax'!$A$14:$H$400,8,FALSE),"") | Z21: =IF(OR(Y21="",X21=""),"",Y21*'Transfer Tax'!$B$6*X21) | AE21: 2026-10-25
A22: 77NOV26 | B22: GD-24-010617 | C22: 1057 Crest Dr | D22: Crescent | E22: 15046 | F22: Crescent | G22: 811-F-380 | H22: 0811-F-00380-0000-00 | I22: Residential / unspecified | J22: Tax lien (Sci Fa sur tax lien) | K22: Individual | L22: Miller, Tim | M22: Crescent Township | N22: WEISS BURKARDT KRAMER LLC | O22: 130186.34 | Q22: 130186.34 | S22: ✔ ✔ – ✔ | T22: Sheriff OK box checked | V22: OK TO SELL 11/2/26 | W22: Crescent Twp | X22: =IFERROR(VLOOKUP(W22,'Transfer Tax'!$A$14:$H$400,8,FALSE),"") | Z22: =IF(OR(Y22="",X22=""),"",Y22*'Transfer Tax'!$B$6*X22) | AE22: 2026-10-25
A23: 86SEP26 | B23: MG-25-000402 | C23: 963 Harper Rd | D23: Crescent | E23: 15046 | F23: Crescent | G23: 811-B-216 | H23: 0811-B-00216-0000-00 | I23: Residential / unspecified | J23: Mortgage foreclosure | K23: Individual | L23: Clapperton, Benjamin W. | M23: Freedom Mortgage Corporation | N23: ORLANS PC | O23: 3267.87 | Q23: 3267.87 | R23: 252986.21 | S23: ✔ ✔ ✔ ✔ | T23: Sheriff OK box checked | V23: RCVD O/C TO REASSESS DAMAGES $252,986.21 OK TO SELL 11-2-26 | W23: Crescent Twp | X23: =IFERROR(VLOOKUP(W23,'Transfer Tax'!$A$14:$H$400,8,FALSE),"") | Z23: =IF(OR(Y23="",X23=""),"",Y23*'Transfer Tax'!$B$6*X23) | AE23: 2026-10-25
A24: 34NOV26 | B24: GD-22-011463 | C24: 423 Hillview Street | D24: Duquesne | E24: 15110 | F24: Duquesne | G24: 305-M-78 | H24: 0305-M-00078-0000-00 | I24: Residential / unspecified | J24: Tax lien (Sci Fa sur tax lien) | K24: Individual | L24: Hill, Sherri L | M24: Duquesne City School District | N24: KRATZENBERG & LAZZARO | O24: 57324.9 | Q24: 57324.9 | S24: ✔ ✔ – ✔ | T24: Sheriff OK box checked | V24: OK TO SELL 11/2/26 | W24: Duquesne City | X24: =IFERROR(VLOOKUP(W24,'Transfer Tax'!$A$14:$H$400,8,FALSE),"") | Z24: =IF(OR(Y24="",X24=""),"",Y24*'Transfer Tax'!$B$6*X24) | AE24: 2026-10-25
A25: 34SEP26 | B25: MG-24-000023 | C25: 160 Lincoln Hall Road | D25: Elizabeth | E25: 15037 | F25: Elizabeth Twp | G25: 1130-D-138 | H25: 1130-D-00138-0000-00 | I25: Residential / unspecified | J25: Mortgage foreclosure | K25: Individual | L25: Miller, Jonathan M. | M25: Lakeview Loan Servicing LLC | N25: ORLANS PC | O25: 4210.85 | Q25: 4210.85 | S25: ✔ ✔ ✔ ✔ | T25: Sheriff OK box checked | V25: PLEASE PROVIDE PP LETTER (3129.3 FOR THE NEXT SHERIFF SALE IS NOT A PP LETTER AND WILL NOT BE ACCEPTED, ANY PHYSICAL 3129.3 WE RECEIVE IS A $50 R&I CHARGE) PLEASE UPLOAD ALL FUTURE 3129.3 TO THE ATTORNEY PORTAL OK TO SELL 11-2-26 | W25: Elizabeth Twp | X25: =IFERROR(VLOOKUP(W25,'Transfer Tax'!$A$14:$H$400,8,FALSE),"") | Z25: =IF(OR(Y25="",X25=""),"",Y25*'Transfer Tax'!$B$6*X25) | AE25: 2026-10-25
A26: 115JUL26 | B26: GD-19-011837 | C26: 404 Park Ave | D26: Elizabeth | E26: 15037 | F26: Elizabeth Twp | G26: 1132-L-254 | H26: 1132-L-00254-0000-00 | I26: Residential / unspecified | J26: Tax lien (Sci Fa sur tax lien) | K26: Individual | L26: Detwiler, Mary Jane | M26: County of Allegheny | N26: GOEHRING RUTTER & BOEHM | O26: 61329.1 | P26: 7800 | Q26: 7800 | S26: ✔ ✔ ✔ ✔ | T26: Sheriff OK box checked | U26: Free & clear court order, min bid $7,800.00 Prior winning bidder forfeited (property re-offered) | V26: OK TO SELL 11-2-26 FORFEITED 10/5/26 F/C O/C FOR A MIN BID OF $7,800.00 | W26: Elizabeth Twp | X26: =IFERROR(VLOOKUP(W26,'Transfer Tax'!$A$14:$H$400,8,FALSE),"") | Z26: =IF(OR(Y26="",X26=""),"",Y26*'Transfer Tax'!$B$6*X26) | AE26: 2026-10-25
A27: 32NOV26 | B27: MG-25-000719 | C27: 304 Pappan Dr | D27: Imperial | E27: 15126 | F27: Findlay | G27: 801-L-34 | H27: 0801-L-00034-0000-00 | I27: Residential / unspecified | J27: Mortgage foreclosure | K27: Individual | L27: GREEN, SABRINA M. | M27: Midfirst Bank | N27: PURCELL KRUG & HALLER | O27: 4045.77 | Q27: 4045.77 | S27: ✔ ✔ – ✔ | T27: Sheriff OK box checked | V27: OK TO SELL 11/2/26 | W27: Findlay Twp | X27: =IFERROR(VLOOKUP(W27,'Transfer Tax'!$A$14:$H$400,8,FALSE),"") | Z27: =IF(OR(Y27="",X27=""),"",Y27*'Transfer Tax'!$B$6*X27) | AE27: 2026-10-25
A28: 147NOV26 | B28: GD-25-007632 | C28: 4018 Greensburg Pike | D28: Pittsburgh | E28: 15221 | F28: Forest Hills | G28: 372-P-54 | H28: 0372-P-00054-0000-00 | I28: Residential / unspecified | J28: Tax lien (Sci Fa sur tax lien) | K28: Individual | L28: Stratiff, David J. | M28: Woodland Hills School District | N28: GOEHRING RUTTER & BOEHM | O28: 27434.66 | Q28: 27434.66 | S28: ✔ ✔ – ✔ | T28: Sheriff OK box checked | V28: OK TO SELL 11/2/26 | W28: Forest Hills Boro | X28: =IFERROR(VLOOKUP(W28,'Transfer Tax'!$A$14:$H$400,8,FALSE),"") | Z28: =IF(OR(Y28="",X28=""),"",Y28*'Transfer Tax'!$B$6*X28) | AE28: 2026-10-25
A29: 110NOV26 | B29: MG-26-000588 | C29: 711 Vermont Avenue | D29: Glassport | E29: 15045 | F29: Glassport | G29: 558-G-273 | H29: 0558-G-00273-0000-00 | I29: Residential / unspecified | J29: Mortgage foreclosure | K29: Individual | L29: Koroly, Michael P | M29: U.S. Bank National Association | N29: PURCELL KRUG & HALLER | O29: 3031.99 | Q29: 3031.99 | S29: ✔ ✔ – ✔ | T29: Sheriff OK box checked | U29: FHA-insured loan | V29: FHA OK TO SELL 11/2/26 | W29: Glassport Boro | X29: =IFERROR(VLOOKUP(W29,'Transfer Tax'!$A$14:$H$400,8,FALSE),"") | Z29: =IF(OR(Y29="",X29=""),"",Y29*'Transfer Tax'!$B$6*X29) | AE29: 2026-10-25
A30: 125NOV26 | B30: GD-14-021137 | C30: 36 Rich Hill Road | D30: Cheswick | E30: 15024 | F30: Harmar | G30: 623-C-30 | H30: 0623-C-00030-0000-00 | I30: Residential / unspecified | J30: Tax lien (Sci Fa sur tax lien) | K30: Individual | L30: Smiesko, Lisa A | M30: County Of Allegheny | N30: GOEHRING RUTTER & BOEHM | O30: 66060.68 | Q30: 66060.68 | S30: ✔ ✔ – ✔ | T30: Sheriff OK box checked | V30: OK TO SELL 11/2/26 | W30: Harmar Twp | X30: =IFERROR(VLOOKUP(W30,'Transfer Tax'!$A$14:$H$400,8,FALSE),"") | Z30: =IF(OR(Y30="",X30=""),"",Y30*'Transfer Tax'!$B$6*X30) | AE30: 2026-10-25
A31: 42APR26 | B31: GD-25-011355 | C31: 214 Burwick Court | D31: Pittsburgh | E31: 15238 | F31: Indiana | G31: 835-A-1 | H31: 0835-A-00001-0000-00 | I31: Residential / unspecified | J31: Mortgage foreclosure | K31: Individual | L31: Grimsley, Douglas M. | M31: Federal Home Loan Mortgage Corporation | N31: ROBERTSON ANSCHUTZ SCHNEID | O31: 4766.99 | Q31: 4766.99 | R31: 169975.36 | S31: ✔ ✔ ✔ ✔ | T31: Sheriff OK box checked | V31: OK TO SELL 11-2-26 O/C TO REASSESS DAMAGES TO $169,975.36 | W31: Indiana Twp | X31: =IFERROR(VLOOKUP(W31,'Transfer Tax'!$A$14:$H$400,8,FALSE),"") | Z31: =IF(OR(Y31="",X31=""),"",Y31*'Transfer Tax'!$B$6*X31) | AE31: 2026-10-25
A32: 6NOV26 | B32: GD-24-005281 | C32: 124 Wray Large Road | D32: Clairton | E32: 15025 | F32: Jefferson Hills | G32: 659-C-186 | H32: 0659-C-00186-0000-00 | I32: Residential / unspecified | J32: Tax lien (Sci Fa sur tax lien) | K32: Individual | L32: Killen, Albert J. | M32: West Jefferson Hills School District | N32: WEISS BURKARDT KRAMER LLC | O32: 65779.59 | Q32: 65779.59 | S32: ✔ ✔ – ✔ | T32: Sheriff OK box checked | V32: OK TO SELL 11/2/26 | W32: Jefferson Hills Boro | X32: =IFERROR(VLOOKUP(W32,'Transfer Tax'!$A$14:$H$400,8,FALSE),"") | Z32: =IF(OR(Y32="",X32=""),"",Y32*'Transfer Tax'!$B$6*X32) | AE32: 2026-10-25
A33: 5NOV26 | B33: GD-25-001437 | C33: 2017 Ridge Road | D33: Finleyville | E33: 15332 | F33: Jefferson Hills | G33: 1136-B-216 | H33: 1136-B-00216-0000-00 | I33: Residential / unspecified | J33: Tax lien (Sci Fa sur tax lien) | K33: Individual | L33: Kinneer, David | M33: West Jefferson Hills School District | N33: WEISS BURKARDT KRAMER LLC | O33: 34615.99 | Q33: 34615.99 | S33: ✔ ✔ – ✔ | T33: Sheriff OK box checked | V33: OK TO SELL 11/2/26 | W33: Jefferson Hills Boro | X33: =IFERROR(VLOOKUP(W33,'Transfer Tax'!$A$14:$H$400,8,FALSE),"") | Z33: =IF(OR(Y33="",X33=""),"",Y33*'Transfer Tax'!$B$6*X33) | AE33: 2026-10-25
A34: 18JAN26 | B34: GD-25-002385 | C34: 3069 Scotia Hollow Road | D34: West Elizabeth | E34: 15088 | F34: Jefferson Hills | G34: 1134-M-150 | H34: 1134-M-00150-0000-00 | I34: Residential / unspecified | J34: Tax lien (Sci Fa sur tax lien) | K34: Individual | L34: Plants, David G. | M34: Jefferson Hills Borough | N34: MAIELLO BRUNGO & MAIELLO | O34: 43283.67 | P34: 7000 | Q34: 7000 | S34: ✔ ✔ ✔ ✔ | T34: Sheriff OK box checked | U34: Free & clear court order, min bid $7,000.00 | V34: OK TO SELL 11-2-26 F/C O/C FOR A MIN BID OF $7,000.00 | W34: Jefferson Hills Boro | X34: =IFERROR(VLOOKUP(W34,'Transfer Tax'!$A$14:$H$400,8,FALSE),"") | Z34: =IF(OR(Y34="",X34=""),"",Y34*'Transfer Tax'!$B$6*X34) | AE34: 2026-10-25
A35: 92NOV26 | B35: GD-25-004770 | C35: 28 Victory Lane | D35: Leetsdale | E35: 15056 | F35: Leetsdale | G35: 704-L-163 | H35: 0704-L-00163-0000-00 | I35: Residential / unspecified | J35: Tax lien (Sci Fa sur tax lien) | K35: Individual | L35: Wytiaz, Barbara | M35: Quaker Valley School District | N35: GOEHRING RUTTER & BOEHM | O35: 11985.17 | Q35: 11985.17 | S35: ✔ ✔ – ✔ | T35: Sheriff OK box checked | V35: OK TO SELL 11/2/26 | W35: Leetsdale Boro | X35: =IFERROR(VLOOKUP(W35,'Transfer Tax'!$A$14:$H$400,8,FALSE),"") | Z35: =IF(OR(Y35="",X35=""),"",Y35*'Transfer Tax'!$B$6*X35) | AE35: 2026-10-25
A36: 81NOV26 | B36: GD-26-000638 | C36: 160 Mount Pleasant Rd | D36: Warrendale | E36: 15086 | F36: Marshall | G36: 1999-B-6 | H36: 1999-B-00006-0000-00 | I36: Residential / unspecified | J36: Mortgage foreclosure | K36: Individual | L36: Halpin III, Charles A.J. | M36: Citizens Bank N.A. | N36: GREGORY JAVARDIAN ESQ | O36: 8579.56 | Q36: 8579.56 | S36: ✔ ✔ – ✔ | T36: Sheriff OK box checked | V36: OK TO SELL 11/2/26 | W36: Marshall Twp | X36: =IFERROR(VLOOKUP(W36,'Transfer Tax'!$A$14:$H$400,8,FALSE),"") | Z36: =IF(OR(Y36="",X36=""),"",Y36*'Transfer Tax'!$B$6*X36) | AE36: 2026-10-25
A37: 22JUN26 | B37: MG-25-000865 | C37: 324 Catherine Street | D37: Mckees Rocks | E37: 15136 | F37: McKees Rocks | G37: 74-R-21 | H37: 0074-R-00021-0000-00 | I37: Residential / unspecified | J37: Mortgage foreclosure | K37: Individual | L37: Taravella, Divauna | M37: Citibank N.A. | N37: ROBERTSON ANSCHUTZ SCHNEID | O37: 9606.04 | Q37: 9606.04 | R37: 56990.25 | S37: ✔ ✔ ✔ ✔ | T37: Sheriff OK box checked | U37: Prior winning bidder forfeited (property re-offered) | V37: OK TO SELL 11-2-26 FORFEITED 10/5/26 O/C TO RE-ASSESS DAMAGES TO $56,990.25 RCVD 9/4/26 | W37: McKees Rocks Boro | X37: =IFERROR(VLOOKUP(W37,'Transfer Tax'!$A$14:$H$400,8,FALSE),"") | Z37: =IF(OR(Y37="",X37=""),"",Y37*'Transfer Tax'!$B$6*X37) | AE37: 2026-10-25
A38: 61NOV26 | B38: MG-26-000208 | C38: 709 Latrobe Street Street | D38: Mckeesport | E38: 15133 | F38: McKees Rocks | G38: 465-L-273 | H38: 0465-L-00273-0000-00 | I38: Residential / unspecified | J38: Mortgage foreclosure | K38: Individual | L38: Karpeal, Jacob P | M38: Pennymac Loan Services LLC | N38: POWERS KIRN LLC | O38: 1889.3 | Q38: 1889.3 | S38: ✔ ✔ – ✔ | T38: Sheriff OK box checked | V38: OK TO SELL 11/2/26 | W38: McKees Rocks Boro | X38: =IFERROR(VLOOKUP(W38,'Transfer Tax'!$A$14:$H$400,8,FALSE),"") | Z38: =IF(OR(Y38="",X38=""),"",Y38*'Transfer Tax'!$B$6*X38) | AE38: 2026-10-25
A39: 73OCT26 | B39: GD-23-002702 | C39: 817 Boquet St | D39: Mc Kees Rocks | E39: 15136 | F39: McKees Rocks | G39: 43-E-170 | H39: 0043-E-00170-0000-00 | I39: Residential / unspecified | J39: Tax lien (Sci Fa sur tax lien) | K39: Estate / heirs / trust | L39: Trautman Admin of Estate Joan Trautman, Ronald | M39: McKees Rocks Borough | N39: GOEHRING RUTTER & BOEHM | O39: 30916.14 | Q39: 30916.14 | S39: ✔ ✔ ✔ ✔ | T39: Sheriff OK box checked | V39: OK TO SELL 11/2/26 | W39: McKees Rocks Boro | X39: =IFERROR(VLOOKUP(W39,'Transfer Tax'!$A$14:$H$400,8,FALSE),"") | Z39: =IF(OR(Y39="",X39=""),"",Y39*'Transfer Tax'!$B$6*X39) | AE39: 2026-10-25
A40: 88NOV26 | B40: GD-23-011031 | C40: 207 Erie St | D40: Mc Keesport | E40: 15132 | F40: McKeesport | G40: 308-F-72 | H40: 0308-F-00072-0000-00 | I40: Residential / unspecified | J40: Tax lien (Sci Fa sur tax lien) | K40: Individual | L40: Thomas, Julian | M40: City of McKeesport | N40: KRATZENBERG & LAZZARO | O40: 24077.56 | Q40: 24077.56 | S40: ✔ ✔ – ✔ | T40: Sheriff OK box checked | V40: OK TO SELL 11/2/26 | W40: McKeesport City | X40: =IFERROR(VLOOKUP(W40,'Transfer Tax'!$A$14:$H$400,8,FALSE),"") | Z40: =IF(OR(Y40="",X40=""),"",Y40*'Transfer Tax'!$B$6*X40) | AE40: 2026-10-25
A41: 6MAY26 | B41: MG-25-000627 | C41: 121 Lippert St | D41: Pittsburgh | E41: 15209 | F41: Millvale | G41: 118-P-70 | H41: 0118-P-00070-0000-00 | I41: Residential / unspecified | J41: Mortgage foreclosure | K41: Individual | L41: Callos, David William | M41: Wilmington Savings Fund Society FSB | N41: ROBERTSON ANSCHUTZ SCHNEID | O41: 6071.64 | Q41: 6071.64 | R41: 229568.47 | S41: ✔ ✔ ✔ ✔ | T41: Sheriff OK box checked | V41: OK TO SELL 11-2-26 RCVD O/C ON 10-13-26 TO REASSESS DAMAGES TO $229,568.47 | W41: Millvale Boro | X41: =IFERROR(VLOOKUP(W41,'Transfer Tax'!$A$14:$H$400,8,FALSE),"") | Z41: =IF(OR(Y41="",X41=""),"",Y41*'Transfer Tax'!$B$6*X41) | AE41: 2026-10-25
...

Sheet Almost Ready
A1: Almost Ready — Mon Nov 2
A2: Active residential cases where Service and 3129.2 are done and only Rule 3129.3 is still needed (often filed at the last minute), plus VERIFY cases where the OK box and notes disagree.
A4: Sale ID | B4: Case # | C4: Property address | D4: City | E4: ZIP | F4: Municipality | G4: Parcel ID(s) | H4: County parcel ID (portal format) | I4: Property type | J4: Sale category | K4: Owner type | L4: Defendant / owner | M4: Plaintiff | N4: Plaintiff attorney | O4: Cost & Tax bid | P4: Free & clear min bid | Q4: Opening bid to watch | R4: Reassessed damages (judgment) | S4: Boxes Svs · 3129.2 · 3129.3 · OK | T4: What's still missing | U4: Flags / title & bidding risks | V4: Sheriff comments (verbatim) | W4: Transfer tax municipality | X4: Transfer tax rate (total) | Y4: YOUR ENTRY: Assessed value | Z4: Est. transfer tax on sheriff deed | AA4: YOUR ENTRY: Max bid | AB4: YOUR ENTRY: My notes | AC4: YOUR ENTRY: Sold for | AD4: YOUR ENTRY: Bidder # | AE4: First listed here
A5: 1SEP26 | B5: GD-22-008550 | C5: 221 Walnut St | D5: Pittsburgh | E5: 15238 | F5: Blawnox | G5: 292-N-392 | H5: 0292-N-00392-0000-00 | I5: Residential / unspecified | J5: Tax lien (Sci Fa sur tax lien) | K5: Individual | L5: RABINOWITZ, JACK | M5: Blawnox Borough | N5: KRATZENBERG & LAZZARO | O5: 36807.63 | Q5: 36807.63 | S5: ✔ ✔ – – | T5: Only Rule 3129.3 outstanding • Rule 3129.3 notice of postponed sale date (for 11/2/26) | V5: NEED 3129.3 FOR 11-2-26 | W5: Blawnox Boro | X5: =IFERROR(VLOOKUP(W5,'Transfer Tax'!$A$14:$H$400,8,FALSE),"") | Z5: =IF(OR(Y5="",X5=""),"",Y5*'Transfer Tax'!$B$6*X5) | AE5: 2026-10-25
A6: 62JAN26 | B6: GD-25-003317 | C6: 2086 Smithdale Rd | D6: West Newton | E6: 15089 | F6: Elizabeth Twp | G6: 1732-S-226 | H6: 1732-S-00226-0000-00 | I6: Residential / unspecified | J6: Tax lien (Sci Fa sur tax lien) | K6: Estate / heirs / trust | L6: Unknown Heirs of Urcell Nicholson aka Vienna Ercel Nicholson | M6: Elizabeth Forward School District | N6: MAIELLO BRUNGO & MAIELLO | O6: 15431.56 | Q6: 15431.56 | S6: ✔ ✔ – – | T6: Only Rule 3129.3 outstanding • Rule 3129.3 notice of postponed sale date (for 11/2/26) | V6: NEED 3129.3 FOR 11-2-26 | W6: Elizabeth Twp | X6: =IFERROR(VLOOKUP(W6,'Transfer Tax'!$A$14:$H$400,8,FALSE),"") | Z6: =IF(OR(Y6="",X6=""),"",Y6*'Transfer Tax'!$B$6*X6) | AE6: 2026-10-25
A7: 4SEP26 | B7: GD-24-011990 | C7: 1615 Sumac St | D7: Mc Keesport | E7: 15132 | F7: McKeesport | G7: 381-G-63 | H7: 0381-G-00063-0000-00 | I7: Residential / unspecified | J7: Tax lien (Sci Fa sur tax lien) | K7: Entity (LLC/LP/Inc) | L7: Next Level Development LLC | M7: City of McKeesport | N7: KRATZENBERG & LAZZARO | O7: 44590.13 | Q7: 44590.13 | S7: ✔ ✔ – – | T7: Only Rule 3129.3 outstanding • Rule 3129.3 notice of postponed sale date (for 11/2/26) | V7: NEED 3129.3 FOR 11-2-26 | W7: McKeesport City | X7: =IFERROR(VLOOKUP(W7,'Transfer Tax'!$A$14:$H$400,8,FALSE),"") | Z7: =IF(OR(Y7="",X7=""),"",Y7*'Transfer Tax'!$B$6*X7) | AE7: 2026-10-25
A8: 29OCT26 | B8: MG-26-000156 | C8: 2417 Riverview St | D8: Mc Keesport | E8: 15132 | F8: McKeesport | G8: 381-N-103 | H8: 0381-N-00103-0000-00 | I8: Residential / unspecified | J8: Mortgage foreclosure | K8: Entity (LLC/LP/Inc) | L8: Pittsburg Luxe LLC | M8: Wilmington Savings Fund Society FSB | N8: FRIEDMAN VARTOLO LLP | O8: 2965.14 | Q8: 2965.14 | S8: ✔ ✔ – – | T8: Only Rule 3129.3 outstanding • Rule 3129.3 notice of postponed sale date (for 11/2/26) | V8: NEED 3129.3 FOR 11-2-26 | W8: McKeesport City | X8: =IFERROR(VLOOKUP(W8,'Transfer Tax'!$A$14:$H$400,8,FALSE),"") | Z8: =IF(OR(Y8="",X8=""),"",Y8*'Transfer Tax'!$B$6*X8) | AE8: 2026-10-25
A9: 46JUL26 | B9: MG-26-000026 | C9: 1303 Craigview Drive | D9: Pittsburgh | E9: 15243 | F9: Mount Lebanon | G9: 194-C-131 | H9: 0194-C-00131-0000-00 | I9: Residential / unspecified | J9: Mortgage foreclosure | K9: Individual | L9: Whaley, Martin G. | M9: Wells Fargo Bank National Association | N9: McCalla Raymer Leibert Pierce LLC | O9: 30650.91 | Q9: 30650.91 | S9: ✔ ✔ – – | T9: Only Rule 3129.3 outstanding • Rule 3129.3 notice of postponed sale date – filed copy rejected, must be re-filed | U9: Save Your Home program involvement | V9: CANNOT GO TO SALE ON 11-2-26 CONCILIATION CONFERENCE RESCHEDULED TO 10-23-26 PP TO 10/5/26 FOR DEF TO APPLY FOR THE SAVE YOUR HOME PROGRAM 3129.3 NOT ACCEPTED NEEDS TO HAVE ATTORNEY SIGNATURE AND CONTACT INFORMATION ON EVERY DOCUMENT | W9: Mount Lebanon Municipality | X9: =IFERROR(VLOOKUP(W9,'Transfer Tax'!$A$14:$H$400,8,FALSE),"") | Z9: =IF(OR(Y9="",X9=""),"",Y9*'Transfer Tax'!$B$6*X9) | AE9: 2026-10-25
A10: 5OCT26 | B10: GD-25-013736 | C10: 950 Margaretta Ave | D10: Pittsburgh | E10: 15234 | F10: Mount Lebanon | G10: 250-E-234 | H10: 0250-E-00234-0000-00 | I10: Residential / unspecified | J10: Tax lien (Sci Fa sur tax lien) | K10: Individual | L10: Edwards Realty & Associates L.P. | M10: Mt. Lebanon School District | N10: WEISS BURKARDT KRAMER LLC | O10: 36309.45 | Q10: 36309.45 | S10: ✔ ✔ – – | T10: Only Rule 3129.3 outstanding • Rule 3129.3 notice of postponed sale date (for 11/2/26) | V10: NEED 3129.3 FOR 11-2-26 | W10: Mount Lebanon Municipality | X10: =IFERROR(VLOOKUP(W10,'Transfer Tax'!$A$14:$H$400,8,FALSE),"") | Z10: =IF(OR(Y10="",X10=""),"",Y10*'Transfer Tax'!$B$6*X10) | AE10: 2026-10-25
A11: 3AUG26 | B11: GD-24-014344 | C11: 2429 Perry St | D11: Homestead | E11: 15120 | F11: Munhall | G11: 181-A-218 | H11: 0181-A-00218-0000-00 | I11: Residential / unspecified | J11: Mortgage foreclosure | K11: Entity (LLC/LP/Inc) | L11: 2429 Perry St. LLC | M11: U.S. Bank Trust National Association | N11: ORLANS PC | O11: 6653.5 | Q11: 6653.5 | R11: 219281.18 | S11: ✔ ✔ – – | T11: Only Rule 3129.3 outstanding • Rule 3129.3 notice of postponed sale date (for 11/2/26) | V11: RCVD O/C TO REASSESS DAMAGES $219,281.18 ON 6/24/26 NEED 3129.3 FOR 11-2-26 | W11: Munhall Boro | X11: =IFERROR(VLOOKUP(W11,'Transfer Tax'!$A$14:$H$400,8,FALSE),"") | Z11: =IF(OR(Y11="",X11=""),"",Y11*'Transfer Tax'!$B$6*X11) | AE11: 2026-10-25
A12: 106MAR26 | B12: GD-24-010373 | C12: 606 E 14th Ave | D12: Homestead | E12: 15120 | F12: Munhall | G12: 130-S-267 | H12: 0130-S-00267-0000-00 | I12: Residential / unspecified | J12: Tax lien (Sci Fa sur tax lien) | K12: Individual | L12: Pacelli, Jeanine A. | M12: Borough of Munhall | N12: LEGAL TAX SERVICE | O12: 65577.98 | Q12: 65577.98 | S12: ✔ ✔ ✔ – | T12: VERIFY – Service/3129.2/3129.3 checked, OK not yet checked, no items listed | W12: Munhall Boro | X12: =IFERROR(VLOOKUP(W12,'Transfer Tax'!$A$14:$H$400,8,FALSE),"") | Z12: =IF(OR(Y12="",X12=""),"",Y12*'Transfer Tax'!$B$6*X12) | AE12: 2026-10-25
A13: 47SEP26 | B13: GD-22-012990 | C13: 618 East 9th Avenue | D13: Homestead | E13: 15120 | F13: Munhall | G13: 130-M-143 | H13: 0130-M-00143-0000-00 | I13: Residential / unspecified | J13: Tax lien (Sci Fa sur tax lien) | K13: Individual | L13: Green, Sharifa B. | M13: Munhall Borough | N13: LEGAL TAX SERVICE | O13: 8596.8 | Q13: 8596.8 | S13: ✔ ✔ – – | T13: Only Rule 3129.3 outstanding • Rule 3129.3 notice of postponed sale date (for 11/2/26) | V13: NEED 3129.3 FOR 11-2-26 | W13: Munhall Boro | X13: =IFERROR(VLOOKUP(W13,'Transfer Tax'!$A$14:$H$400,8,FALSE),"") | Z13: =IF(OR(Y13="",X13=""),"",Y13*'Transfer Tax'!$B$6*X13) | AE13: 2026-10-25
A14: 3SEP26 | B14: GD-24-004175 | C14: 14 Greenwich Court | D14: Oakmont | E14: 15139 | F14: Oakmont | G14: 444-K-21-14 | H14: search by address | I14: Residential / unspecified | J14: Tax lien (Sci Fa sur tax lien) | K14: Individual | L14: Grogg, Melynda C | M14: Oakmont Borough | N14: KRATZENBERG & LAZZARO | O14: 20647.81 | Q14: 20647.81 | S14: ✔ ✔ – – | T14: Only Rule 3129.3 outstanding • Rule 3129.3 notice of postponed sale date (for 11/2/26) | V14: NEED 3129.3 FOR 11-2-26 | W14: Oakmont Boro | X14: =IFERROR(VLOOKUP(W14,'Transfer Tax'!$A$14:$H$400,8,FALSE),"") | Z14: =IF(OR(Y14="",X14=""),"",Y14*'Transfer Tax'!$B$6*X14) | AE14: 2026-10-25
A15: 9AUG26 | B15: MG-25-000548 | C15: 154 Glenfield Drive | D15: Pittsburgh | E15: 15235 | F15: Penn Hills | G15: 448-K-114 | H15: 0448-K-00114-0000-00 | I15: Residential / unspecified | J15: Mortgage foreclosure | K15: Individual | L15: Wilhoit II, James R. | M15: Federal Home Loan Mortgage Corporation | N15: LOGS LEGAL GROUP LLC | O15: 2967.49 | Q15: 2967.49 | S15: ✔ ✔ ✔ – | T15: VERIFY – notes say OK TO SELL but OK box unchecked | V15: OK TO SELL 11-2-26 | W15: Penn Hills Municipality | X15: =IFERROR(VLOOKUP(W15,'Transfer Tax'!$A$14:$H$400,8,FALSE),"") | Z15: =IF(OR(Y15="",X15=""),"",Y15*'Transfer Tax'!$B$6*X15) | AE15: 2026-10-25
A16: 57SEP26 | B16: GD-25-013585 | C16: 1234 High Street | D16: Pittsburgh | E16: 15212 | F16: Pittsburgh | G16: 24-C-152 | H16: 0024-C-00152-0000-00 | I16: Residential / unspecified | J16: Mortgage foreclosure | K16: Entity (LLC/LP/Inc) | L16: Mansion Global LLC | M16: EF Mortgage LLC | N16: HLADIK ONORATO AND FEDERMAN LLP | O16: 3826.83 | Q16: 3826.83 | S16: ✔ ✔ – – | T16: Only Rule 3129.3 outstanding • Rule 3129.3 notice of postponed sale date (for 11/2/26) | V16: NEED 3129.3 FOR 11-2-26 | W16: Pittsburgh City (Pittsburgh SD) | X16: =IFERROR(VLOOKUP(W16,'Transfer Tax'!$A$14:$H$400,8,FALSE),"") | Z16: =IF(OR(Y16="",X16=""),"",Y16*'Transfer Tax'!$B$6*X16) | AE16: 2026-10-25
A17: 119JUN25 | B17: GD-24-011281 | C17: 2812 Wadlow St | D17: Pittsburgh | E17: 15212 | F17: Pittsburgh | G17: 45-B-13 | H17: 0045-B-00013-0000-00 | I17: Residential / unspecified | J17: Mortgage foreclosure | K17: Entity (LLC/LP/Inc) | L17: FERRELL HOLDINGS LLC | M17: Athene Annuity and Life Company | N17: FRIEDMAN VARTOLO LLP | O17: 16622.72 | Q17: 16622.72 | R17: 170646.35 | S17: ✔ ✔ – – | T17: Only Rule 3129.3 outstanding • Rule 3129.3 notice of postponed sale date (for 11/2/26) – filed copy rejected, must be re-filed | V17: 3129.3 FOR 11-2-26 NOT ACCEPTED THERE IS NO FILING DATE ON DOCUMENTS (10-22-26) O/C TO REASSESS DAMAGES TO $170,646.35 | W17: Pittsburgh City (Pittsburgh SD) | X17: =IFERROR(VLOOKUP(W17,'Transfer Tax'!$A$14:$H$400,8,FALSE),"") | Z17: =IF(OR(Y17="",X17=""),"",Y17*'Transfer Tax'!$B$6*X17) | AE17: 2026-10-25
A18: 10OCT26 | B18: GD-26-002368 | C18: 2914 Glasgow St | D18: Pittsburgh | E18: 15204 | F18: Pittsburgh | G18: 21-J-186 | H18: 0021-J-00186-0000-00 | I18: Residential / unspecified | J18: Mortgage foreclosure | K18: Entity (LLC/LP/Inc) | L18: Sheraden Redevelopment Group LP | M18: U.S. Bank Trust Company National Association | N18: FRIEDMAN VARTOLO LLP | O18: 1858.7 | Q18: 1858.7 | R18: 177331.16 | S18: ✔ ✔ – – | T18: Only Rule 3129.3 outstanding • Rule 3129.3 notice of postponed sale date (for 11/2/26) | V18: RCVD O/C TO REASSESS DAMAGES $177,331.16 NEED 3129.3 FOR 11-2-26 | W18: Pittsburgh City (Pittsburgh SD) | X18: =IFERROR(VLOOKUP(W18,'Transfer Tax'!$A$14:$H$400,8,FALSE),"") | Z18: =IF(OR(Y18="",X18=""),"",Y18*'Transfer Tax'!$B$6*X18) | AE18: 2026-10-25
A19: 85JUL25 | B19: GD-24-010996 | C19: 1204 Washington Boulevard Rear | D19: Mckeesport | E19: 15133 | F19: Port Vue | G19: 383-G-116 | H19: 0383-G-00116-0000-00 | I19: Residential / unspecified | J19: Tax lien (Sci Fa sur tax lien) | K19: Individual | L19: Rectenwald, Scott | M19: South Allegheny School District | N19: MAIELLO BRUNGO & MAIELLO | O19: 24808.23 | Q19: 24808.23 | S19: ✔ ✔ ✔ – | T19: VERIFY – Service/3129.2/3129.3 checked, OK not yet checked, no items listed | U19: Bankruptcy history: 1 filing(s) | V19: CHP 13 CN 25-21736 FILED ON 7/1/25 BKD RCVD 6-29-26 | W19: Port Vue Boro | X19: =IFERROR(VLOOKUP(W19,'Transfer Tax'!$A$14:$H$400,8,FALSE),"") | Z19: =IF(OR(Y19="",X19=""),"",Y19*'Transfer Tax'!$B$6*X19) | AE19: 2026-10-25
A20: 104AUG26 | B20: MG-24-000780 | C20: 90 Highland Ave | D20: Mc Kees Rocks | E20: 15136 | F20: Stowe | G20: 73-S-277 | H20: 0073-S-00277-0000-00 | I20: Residential / unspecified | J20: Mortgage foreclosure | K20: Entity (LLC/LP/Inc) | L20: Royal Realty by TLM LLC | M20: U.S. Bank Trust Company National Association | N20: McCalla Raymer Leibert Pierce LLC | O20: 10813.64 | Q20: 10813.64 | S20: ✔ ✔ – – | T20: Only Rule 3129.3 outstanding • Rule 3129.3 notice of postponed sale date (for 11/2/26) | V20: NEED 3129.3 FOR 11-2-26 | W20: Stowe Twp | X20: =IFERROR(VLOOKUP(W20,'Transfer Tax'!$A$14:$H$400,8,FALSE),"") | Z20: =IF(OR(Y20="",X20=""),"",Y20*'Transfer Tax'!$B$6*X20) | AE20: 2026-10-25
A21: 55AUG26 | B21: GD-17-009395 | C21: 1800 Montier St | D21: Pittsburgh | E21: 15221 | F21: Wilkinsburg | G21: 232-M-47 | H21: 0232-M-00047-0000-00 | I21: Residential / unspecified | J21: Tax lien (Sci Fa sur tax lien) | K21: Individual | L21: Cheatham, Nichole | M21: Wilkinsburg Borough | N21: MAIELLO BRUNGO & MAIELLO | O21: 163825.86 | Q21: 163825.86 | S21: ✔ ✔ – – | T21: Only Rule 3129.3 outstanding • Rule 3129.3 notice of postponed sale date (for 11/2/26) | V21: NEED 3129.3 FOR 11-2-26 | W21: Wilkinsburg Boro | X21: =IFERROR(VLOOKUP(W21,'Transfer Tax'!$A$14:$H$400,8,FALSE),"") | Z21: =IF(OR(Y21="",X21=""),"",Y21*'Transfer Tax'!$B$6*X21) | AE21: 2026-10-25

Sheet Transfer Tax
A1: Realty transfer tax — every Allegheny County municipality
A2: Local rates: Allegheny County Dept. of Real Estate 'Local Realty Transfer Tax Rates' page (cross-checked against ALT Title's deviation list as of 7/1/2025 — all 17 non-standard entries match). Names lightly normalized (e.g., 'Mt.'→'Mount').
A4: INPUTS
A5: State realty transfer tax rate | B5: 0.01 | C5: PA Dept. of Revenue — state RTT is 1%.
A6: Allegheny CLR factor | B6: 2.03 | C6: Source: PA Dept. of Revenue CLR factor list for documents accepted 7/1/2026–6/30/2027 (Allegheny = 2.03). The County's own RTT page still shows the older 1.99.
A7: Example assessed value (try your own) | B7: 40000 | C7: Look up a parcel's assessed value on the County Real Estate portal using the 'County parcel ID' column.
A9: HOW THE TAX IS FIGURED ON A SHERIFF DEED
A10: PA Revenue regulation 61 Pa. Code § 91.135: for transfers by execution, mortgage foreclosure, judicial sale or tax sale, the tax base is COMPUTED VALUE = assessed value × CLR factor — not your winning bid. A cheap bid can still carry a real tax bill.
A11: Example computed value | B11: =B7*B6
A13: Municipality | B13: Municipal rate | C13: School district | D13: School rate | E13: Local total | F13: State rate | G13: Note | H13: Total rate | I13: Tax per $10k assessed | J13: On OK to Sell | K13: On Almost Ready
A14: Aleppo Twp | B14: 0.005 | C14: Quaker Valley School District | D14: 0.005 | E14: =B14+D14 | F14: =$B$5 | H14: =E14+F14 | I14: =10000*$B$6*H14 | J14: =COUNTIF('OK to Sell'!$W:$W,A14) | K14: =COUNTIF('Almost Ready'!$W:$W,A14)
A15: Aspinwall Boro | B15: 0.005 | C15: Fox Chapel Area School District | D15: 0.005 | E15: =B15+D15 | F15: =$B$5 | H15: =E15+F15 | I15: =10000*$B$6*H15 | J15: =COUNTIF('OK to Sell'!$W:$W,A15) | K15: =COUNTIF('Almost Ready'!$W:$W,A15)
A16: Avalon Boro | B16: 0.005 | C16: Northgate School District | D16: 0.005 | E16: =B16+D16 | F16: =$B$5 | H16: =E16+F16 | I16: =10000*$B$6*H16 | J16: =COUNTIF('OK to Sell'!$W:$W,A16) | K16: =COUNTIF('Almost Ready'!$W:$W,A16)
A17: Baldwin Boro | B17: 0.005 | C17: Baldwin-Whitehall School District | D17: 0.005 | E17: =B17+D17 | F17: =$B$5 | H17: =E17+F17 | I17: =10000*$B$6*H17 | J17: =COUNTIF('OK to Sell'!$W:$W,A17) | K17: =COUNTIF('Almost Ready'!$W:$W,A17)
A18: Baldwin Twp | B18: 0.005 | C18: Baldwin-Whitehall School District | D18: 0.005 | E18: =B18+D18 | F18: =$B$5 | H18: =E18+F18 | I18: =10000*$B$6*H18 | J18: =COUNTIF('OK to Sell'!$W:$W,A18) | K18: =COUNTIF('Almost Ready'!$W:$W,A18)
A19: Bellevue Boro | B19: 0.01 | C19: Northgate School District | D19: 0.005 | E19: =B19+D19 | F19: =$B$5 | H19: =E19+F19 | I19: =10000*$B$6*H19 | J19: =COUNTIF('OK to Sell'!$W:$W,A19) | K19: =COUNTIF('Almost Ready'!$W:$W,A19)
A20: Bell Acres Boro | B20: 0.005 | C20: Quaker Valley School District | D20: 0.005 | E20: =B20+D20 | F20: =$B$5 | H20: =E20+F20 | I20: =10000*$B$6*H20 | J20: =COUNTIF('OK to Sell'!$W:$W,A20) | K20: =COUNTIF('Almost Ready'!$W:$W,A20)
A21: Ben Avon Boro | B21: 0.005 | C21: Avonworth School District | D21: 0.005 | E21: =B21+D21 | F21: =$B$5 | H21: =E21+F21 | I21: =10000*$B$6*H21 | J21: =COUNTIF('OK to Sell'!$W:$W,A21) | K21: =COUNTIF('Almost Ready'!$W:$W,A21)
A22: Ben Avon Heights Boro | B22: 0.005 | C22: Avonworth School District | D22: 0.005 | E22: =B22+D22 | F22: =$B$5 | H22: =E22+F22 | I22: =10000*$B$6*H22 | J22: =COUNTIF('OK to Sell'!$W:$W,A22) | K22: =COUNTIF('Almost Ready'!$W:$W,A22)
A23: Bethel Park Municipality | B23: 0.01 | C23: Bethel Park School District | D23: 0.005 | E23: =B23+D23 | F23: =$B$5 | H23: =E23+F23 | I23: =10000*$B$6*H23 | J23: =COUNTIF('OK to Sell'!$W:$W,A23) | K23: =COUNTIF('Almost Ready'!$W:$W,A23)
A24: Blawnox Boro | B24: 0.005 | C24: Fox Chapel Area School District | D24: 0.005 | E24: =B24+D24 | F24: =$B$5 | H24: =E24+F24 | I24: =10000*$B$6*H24 | J24: =COUNTIF('OK to Sell'!$W:$W,A24) | K24: =COUNTIF('Almost Ready'!$W:$W,A24)
A25: Brackenridge Boro | B25: 0.005 | C25: Highlands School District | D25: 0.005 | E25: =B25+D25 | F25: =$B$5 | H25: =E25+F25 | I25: =10000*$B$6*H25 | J25: =COUNTIF('OK to Sell'!$W:$W,A25) | K25: =COUNTIF('Almost Ready'!$W:$W,A25)
... A87: Mount Lebanon Municipality | B87: 0.01 | C87: Mt. Lebanon School District | D87: 0.005 | E87: =B87+D87 | F87: =$B$5 | H87: =E87+F87 | I87: =10000*$B$6*H87 | J87: =COUNTIF('OK to Sell'!$W:$W,A87) | K87: =COUNTIF('Almost Ready'!$W:$W,A87)
A88: Mount Oliver Boro | B88: 0.01 | C88: Pittsburgh School District | D88: 0.01 | E88: =B88+D88 | F88: =$B$5 | G88: In the Pittsburgh School District (1% school rate). | H88: =E88+F88 | I88: =10000*$B$6*H88 | J88: =COUNTIF('OK to Sell'!$W:$W,A88) | K88: =COUNTIF('Almost Ready'!$W:$W,A88)
A89: Munhall Boro | B89: 0.005 | C89: Steel Valley School District | D89: 0.005 | E89: =B89+D89 | F89: =$B$5 | H89: =E89+F89 | I89: =10000*$B$6*H89 | J89: =COUNTIF('OK to Sell'!$W:$W,A89) | K89: =COUNTIF('Almost Ready'!$W:$W,A89)
A90: Neville Twp | B90: 0.005 | C90: Cornell School District | D90: 0.005 | E90: =B90+D90 | F90: =$B$5 | H90: =E90+F90 | I90: =10000*$B$6*H90 | J90: =COUNTIF('OK to Sell'!$W:$W,A90) | K90: =COUNTIF('Almost Ready'!$W:$W,A90)
A91: North Braddock Boro | B91: 0.005 | C91: Woodland Hills School District | D91: 0.005 | E91: =B91+D91 | F91: =$B$5 | H91: =E91+F91 | I91: =10000*$B$6*H91 | J91: =COUNTIF('OK to Sell'!$W:$W,A91) | K91: =COUNTIF('Almost Ready'!$W:$W,A91)
A92: North Fayette Twp | B92: 0.005 | C92: West Allegheny School District | D92: 0.005 | E92: =B92+D92 | F92: =$B$5 | H92: =E92+F92 | I92: =10000*$B$6*H92 | J92: =COUNTIF('OK to Sell'!$W:$W,A92) | K92: =COUNTIF('Almost Ready'!$W:$W,A92)
A93: North Versailles Twp | B93: 0.005 | C93: East Allegheny School District | D93: 0.005 | E93: =B93+D93 | F93: =$B$5 | H93: =E93+F93 | I93: =10000*$B$6*H93 | J93: =COUNTIF('OK to Sell'!$W:$W,A93) | K93: =COUNTIF('Almost Ready'!$W:$W,A93)
A94: Oakdale Boro | B94: 0.005 | C94: West Allegheny School District | D94: 0.005 | E94: =B94+D94 | F94: =$B$5 | H94: =E94+F94 | I94: =10000*$B$6*H94 | J94: =COUNTIF('OK to Sell'!$W:$W,A94) | K94: =COUNTIF('Almost Ready'!$W:$W,A94)
A95: Oakmont Boro | B95: 0.005 | C95: Riverview School District | D95: 0.005 | E95: =B95+D95 | F95: =$B$5 | H95: =E95+F95 | I95: =10000*$B$6*H95 | J95: =COUNTIF('OK to Sell'!$W:$W,A95) | K95: =COUNTIF('Almost Ready'!$W:$W,A95)
A96: O'Hara Twp | B96: 0.01 | C96: Fox Chapel Area School District | D96: 0.005 | E96: =B96+D96 | F96: =$B$5 | H96: =E96+F96 | I96: =10000*$B$6*H96 | J96: =COUNTIF('OK to Sell'!$W:$W,A96) | K96: =COUNTIF('Almost Ready'!$W:$W,A96)
A97: Ohio Twp | B97: 0.005 | C97: Avonworth School District | D97: 0.005 | E97: =B97+D97 | F97: =$B$5 | H97: =E97+F97 | I97: =10000*$B$6*H97 | J97: =COUNTIF('OK to Sell'!$W:$W,A97) | K97: =COUNTIF('Almost Ready'!$W:$W,A97)
A98: Pennsbury Village Boro | B98: 0.005 | C98: Montour School District | D98: 0.005 | E98: =B98+D98 | F98: =$B$5 | H98: =E98+F98 | I98: =10000*$B$6*H98 | J98: =COUNTIF('OK to Sell'!$W:$W,A98) | K98: =COUNTIF('Almost Ready'!$W:$W,A98)
A99: Penn Hills Municipality | B99: 0.015 | C99: Penn Hills School District | D99: 0.005 | E99: =B99+D99 | F99: =$B$5 | H99: =E99+F99 | I99: =10000*$B$6*H99 | J99: =COUNTIF('OK to Sell'!$W:$W,A99) | K99: =COUNTIF('Almost Ready'!$W:$W,A99)
A100: Pine Twp | B100: 0.01 | C100: Pine-Richland School District | D100: 0.005 | E100: =B100+D100 | F100: =$B$5 | H100: =E100+F100 | I100: =10000*$B$6*H100 | J100: =COUNTIF('OK to Sell'!$W:$W,A100) | K100: =COUNTIF('Almost Ready'!$W:$W,A100)
A101: Pitcairn Boro | B101: 0.005 | C101: Gateway School District | D101: 0.005 | E101: =B101+D101 | F101: =$B$5 | H101: =E101+F101 | I101: =10000*$B$6*H101 | J101: =COUNTIF('OK to Sell'!$W:$W,A101) | K101: =COUNTIF('Almost Ready'!$W:$W,A101)
A102: Pittsburgh City (Baldwin-Whitehall SD portion) | B102: 0.03 | C102: Baldwin-Whitehall School District | D102: 0.005 | E102: =B102+D102 | F102: =$B$5 | G102: Small part of the City inside Baldwin-Whitehall SD (e.g., parts of the 32nd Ward). Sheet defaults City parcels to 5% — confirm. | H102: =E102+F102 | I102: =10000*$B$6*H102 | J102: =COUNTIF('OK to Sell'!$W:$W,A102) | K102: =COUNTIF('Almost Ready'!$W:$W,A102)
A103: Pittsburgh City (Pittsburgh SD) | B103: 0.03 | C103: Pittsburgh School District | D103: 0.01 | E103: =B103+D103 | F103: =$B$5 | H103: =E103+F103 | I103: =10000*$B$6*H103 | J103: =COUNTIF('OK to Sell'!$W:$W,A103) | K103: =COUNTIF('Almost Ready'!$W:$W,A103)
A104: Pleasant Hills Boro | B104: 0.005 | C104: West Jefferson Hills School District | D104: 0.005 | E104: =B104+D104 | F104: =$B$5 | H104: =E104+F104 | I104: =10000*$B$6*H104 | J104: =COUNTIF('OK to Sell'!$W:$W,A104) | K104: =COUNTIF('Almost Ready'!$W:$W,A104)
...

Sheet Glossary
A1: How to read the Sheriff notes, and what each sale type means for a bidder
A2: Educational, Pennsylvania / Allegheny County context — not legal advice. Title outcomes at a sheriff sale depend on lien priority and notice; have a PA title company or real-estate attorney confirm before bidding on any specific parcel.
A4: SALE TYPES
A5: Tax lien (Sci Fa sur tax lien) | B5: A school district, municipality or the County is enforcing unpaid real-estate tax claims through a writ of scire facias. The Cost & Tax bid is the opening bid covering the claim plus costs. Which other liens are wiped out depends on priority and proper notice — do not assume "free and clear" unless there is a free & clear court order.
A6: Free & clear court order (F/C O/C) + min bid | B6: The court has authorized sale free and clear of liens at the stated minimum bid, which can be far below the listed Cost & Tax bid. Read the actual order on the docket to confirm scope.
A7: Mortgage foreclosure | B7: A lender is selling under its foreclosure judgment. The Cost & Tax bid is only costs and taxes; the lender can credit-bid up to its judgment (see "Reassessed damages"), so outside bidders usually need to beat the lender's announced bid. Liens senior to the mortgage can survive.
A8: HOA / condo assessment judgment | B8: An association is executing on a money judgment for unpaid assessments (AR- case numbers). Because this is usually a junior lien, a first mortgage on the unit may survive the sale — potentially a large hidden liability. Get a title search before bidding.
A9: Other judgment execution | B9: A creditor executing on a general money judgment (e.g., business lenders). Senior liens and mortgages typically survive.
A10: Municipal lien | B10: A municipal claim (non-tax, e.g., sewer/water/demolition) enforced by sheriff sale.
A12: LISTED STATUSES
A13: Active | B13: Scheduled to go to the upcoming sale — but the Sheriff will only sell if the paperwork is complete (see the four boxes and notes).
A14: Postponed / Postponed (Waived) | B14: Moved to the date shown. 12/31/2099 = indefinite (Save Your Home program). The meaning of "(Waived)" is not stated on the list.
A15: Stayed | B15: Sale halted (bankruptcy, payment plan, court order). "Amount realized" = money collected on the stay.
A16: Money Made | B16: The claim was paid/satisfied; the property won't be sold.
A18: THE FOUR BOXES
A19: Svs | B19: Service of the writ/notice on the defendant has been made.
A20: 3129.2 | B20: Pa.R.C.P. 3129.2 — notice of sale (handbills, written notice to owners/lienholders, publication). Written notice must be served at least 30 days before the sale; the Sheriff rejects late ones.
A21: 3129.3 | B21: Pa.R.C.P. 3129.3 — postponement of sale / new notice. Needed when a sale was postponed to this date. Often filed in the last day or two before the sale, which is why cases missing only this item are listed on Almost Ready.
A22: OK | B22: Sheriff has everything needed and has cleared the property to sell on this date.
A24: ABBREVIATIONS IN NOTES
A25: O/C | B25: Order of court. "NEED O/C FOR [dates]" = a court order approving the chain of postponements through those sale dates; the Sheriff rejects orders that skip a date or list them out of sequence.
A26: BK / BKD / BKDR | B26: Bankruptcy / bankruptcy dismissal or relief-from-stay docs. A pending bankruptcy automatically stays the sale until the Sheriff receives the dismissal or relief order.
A27: NSM ON DEF(S) | B27: No service made on the defendant(s) — proof of service still needed.
A28: PP | B28: Postponement.
A29: NOS | B29: Notice of sale.
A30: SYH | B30: Save Your Home — Allegheny County foreclosure-diversion/conciliation program.
A31: Replenishment invoice | B31: Plaintiff owes the Sheriff an additional cost deposit; the case cannot go to sale until paid.
A32: Reassess damages | B32: Court order updating the judgment amount (the most recent figure is shown in the sheet).
A33: Forfeited | B33: A previous winning bidder failed to pay the balance and lost the deposit; the property is being re-offered.
A34: Handbill / short description | B34: Sale advertising materials. If late or incorrect, the Sheriff requires a postponement.
A35: C+T | B35: Cost & Tax (the opening bid).
A37: LIEN FLAGS
A38: Federal tax lien / IRS lien | B38: Whether a federal tax lien is discharged depends on whether the United States was properly joined. When it is joined, the IRS generally keeps a right to redeem (buy back) the property after the sale (28 U.S.C. § 2410(c); IRM 5.12.5).
A39: HOA 6-month statutory amount | B39: PA planned-community and condo statutes give associations limited priority (about six months of assessments) over a first mortgage; the rest of the HOA debt is junior.
A40: PA DHS lien | B40: Commonwealth Dept. of Human Services lien (e.g., estate recovery). Check whether it is divested.
A41: Land bank decree | B41: Land bank involvement noted on the case — confirm whether a land bank intends to bid or has priority before investing time.
A43: METHOD
A44: How readiness was derived | B44: OK to Sell = Active, residential, Sheriff OK box checked, and no outstanding items in the notes other than Rule 3129.3. Almost Ready = Active, residential, Service and 3129.2 boxes checked, and the only outstanding item is Rule 3129.3 — plus "VERIFY" cases where the OK box and the notes disagree. Everything else (postponed, stayed, paid, bankruptcy, court orders or service still needed, commercial / industrial / vacant land) is left off the sheet.
A45: Source | B45: Allegheny County Sheriff — Sale Listings PDF from sheriffalleghenycounty.com/sheriffs-sales/. The Sheriff states the binding bid list is finalized the morning of the sale; the version and print time used for the latest update are on the Overview tab.
A47: TRANSFER TAX
...

Sheet _Data
A1: sale_id | B1: case_no | C1: address | D1: municipality | E1: status | F1: bucket | G1: bucket_reason | H1: opening_bid | I1: flags
A2: 40JUL19 | B2: GD-18-001488 | C2: 227 Marland St | D2: Pittsburgh | E2: Postponed to 5/3/2027 | F2: excluded | G2: Postponed to 5/3/2027 | H2: 45742.95 | I2: Free & clear order at "upset price" Prior winning bidder forfeited (property re-offered) Bankruptcy history: 7 filing(s)
A3: 55DEC19 | B3: GD-16-010596 | C3: 6 Michigan Rd | D3: Penn Hills | E3: Postponed to 1/4/2027 | F3: excluded | G3: Postponed to 1/4/2027 | H3: 36514.43 | I3: Bankruptcy history: 3 filing(s)
A4: 9NOV21 | B4: GD-20-001165 | C4: 109 E 18th Ave | D4: Homestead | E4: Active | F4: excluded | G4: Docs outstanding: Court order (O/C) approving postponements covering 9 sale date(s): 11/4/24, 2/3/25, 3/3/25, 7/7/25, 9/2/25, 12/1/25, 3/2/26, 7/6/26, 8/3/26 | H4: 54086.54
A5: 49JAN22 | B5: GD-15-007385 | C5: 203 E 20th Ave | D5: Munhall | E5: Active | F5: excluded | G5: Docs outstanding: Replenishment invoice must be paid; Court order (O/C) approving postponements covering 12 sale date(s): 12/2/24, 4/7/25, 5/5/25, 7/7/25, 10/6/25, 11/3/25, 2/2/26, 5/4/26, 6/1/26, 8/3/26, 9/8/26, 11/2/26; Rule 3129.3 notice of postponed sale date (for 11/2/26) | H5: 56115.05 | I5: Defense attorney has entered an appearance
A6: 51JAN22 | B6: GD-19-016470 | C6: 4101 Superior St | D6: Munhall | E6: Postponed to 1/4/2027 | F6: excluded | G6: Postponed to 1/4/2027 | H6: 62369.21
A7: 89JAN22 | B7: GD-16-015649 | C7: 3706 Home St | D7: West Mifflin | E7: Postponed to 1/4/2027 | F7: excluded | G7: Postponed to 1/4/2027 | H7: 51324.55
A8: 89JUN22 | B8: MG-20-000017 | C8: 327 Greenway Dr | D8: Penn Hills | E8: Active | F8: excluded | G8: Bankruptcy dismissal / relief-from-stay docs | H8: 3132.68 | I8: Bankruptcy history: 2 filing(s)
A9: 31AUG22 | B9: GD-19-008607 | C9: 109 Lavern St | D9: Penn Hills | E9: Postponed to 12/7/2026 | F9: excluded | G9: Postponed to 12/7/2026 | H9: 70636.94
A10: 5NOV22 | B10: GD-20-008893 | C10: 428 Dennison Dr | D10: West Mifflin | E10: Active | F10: excluded | G10: Docs outstanding: Court order (O/C) approving postponements covering 15 sale date(s): 6/5/23, 3/3/25, 5/5/25, 6/2/25, 7/7/25, 8/4/25, 9/2/25, 11/3/25, 1/5/26, 4/6/26, 5/4/26, 6/1/26, 8/3/26, 9/8/26, 11/2/26 | H10: 37741.72
A11: 43JAN23 | B11: GD-22-005972 | C11: 2146 Sampson St | D11: Penn Hills | E11: Active | F11: excluded | G11: Bankruptcy dismissal / relief-from-stay docs | H11: 31122.59 | I11: Bankruptcy history: 2 filing(s)
A12: 35JUL23 | B12: GD-22-013060 | C12: 26-28 Oak Street | D12: West Deer | E12: Active | F12: excluded | G12: Bankruptcy dismissal / relief-from-stay docs | H12: 44823.2 | I12: Bankruptcy history: 1 filing(s)
A13: 28NOV23 | B13: GD-22-004165 | C13: 2602 Milburn Street | D13: McKeesport | E13: Active | F13: excluded | G13: Docs outstanding: Court order (O/C) approving postponements covering 11 sale date(s): 5/6/24, 7/1/24, 11/4/24, 3/3/25, 6/2/25, 9/2/25, 11/3/25, 2/2/26, 5/4/26, 8/3/26, 11/2/26; Rule 3129.3 notice of postponed sale date (for 11/2/26) | H13: 22299.84
A14: 36APR24 | B14: GD-22-000743 | C14: 741 Michigan Avenue | D14: Glassport | E14: Postponed to 3/1/2027 | F14: excluded | G14: Postponed to 3/1/2027 | H14: 33206.67 | I14: Bankruptcy history: 2 filing(s)
A15: 49AUG24 | B15: GD-23-008764 | C15: Union Ave | D15: McKeesport | E15: Active | F15: excluded | G15: Non-residential (Vacant Land) | H15: 21794.65 | I15: Free & clear order at "upset price"
A16: 2NOV24 | B16: GD-23-014272 | C16: 61 Bellanca Avenue | D16: Brentwood | E16: Active | F16: ok | G16: Sheriff OK box checked | H16: 14000 | I16: Free & clear court order, min bid $14,000.00 Bankruptcy history: 2 filing(s)
A17: 37DEC24 | B17: GD-23-003880 | C17: 1319 S Canal Street ; 1324 Middle St | D17: Sharpsburg | E17: Active | F17: excluded | G17: Docs outstanding: Replenishment invoice must be paid; Rule 3129.3 notice of postponed sale date (for 11/2/26); Court order (O/C) approving postponements covering 7 sale date(s): 11/3/25, 1/5/26, 3/2/26, 5/4/26, 7/6/26, 9/8/26, 11/2/26 | H17: 43057.51
A18: 39DEC24 | B18: GD-24-004172 | C18: 858 Punta Gorda Ave | D18: East McKeesport | E18: Active | F18: excluded | G18: Docs outstanding: Rule 3129.3 notice of postponed sale date (for 11/2/26); Court order (O/C) approving postponements covering 2 sale date(s): 10/5/26, 11/2/26 | H18: 25961.14
A19: 57DEC24 | B19: GD-24-001709 | C19: 117 Spring Grove Road | D19: Penn Hills | E19: Active | F19: excluded | G19: Docs outstanding: Court order (O/C) approving postponements covering 1 sale date(s): 11/2/26 | H19: 34308.17
A20: 86DEC24 | B20: GD-17-014538 | C20: 1651 Ellsworth Ave | D20: Heidelberg | E20: Stayed | F20: excluded | G20: Stayed | H20: 49628.61 | I20: Bankruptcy history: 1 filing(s)
A21: 101DEC24 | B21: GD-23-009031 | C21: 114 S 6th St | D21: Duquesne | E21: Active | F21: excluded | G21: Docs outstanding: Replenishment invoice must be paid; Rule 3129.3 notice of postponed sale date (for 11/2/26); Court order (O/C) approving postponements covering 7 sale date(s): 6/2/25, 9/2/25, 12/1/25, 2/2/26, 5/4/26, 8/3/26, 11/2/26 | H21: 37078.04
A22: 21JAN25 | B22: GD-23-010343 | C22: 931 Morton Avenue | D22: Port Vue | E22: Postponed to 5/3/2027 | F22: excluded | G22: Postponed to 5/3/2027 | H22: 26939.19
A23: 52JAN25 | B23: GD-24-007223 | C23: 820 Mckee St | D23: Wilkinsburg | E23: Active | F23: excluded | G23: Docs outstanding: Court order (O/C) approving postponements covering 1 sale date(s): 11/2/26 | H23: 39223.38 | I23: Bankruptcy history: 1 filing(s)
A24: 55JAN25 | B24: GD-24-003710 | C24: 523 Delaware Ave ; 509 Monongahela Ave | D24: Glassport | E24: Stayed | F24: excluded | G24: Stayed | H24: 38953.12
A25: 71MAR25 | B25: GD-23-010691 | C25: 7134 Doak St | D25: Penn Hills | E25: Postponed to 5/3/2027 | F25: excluded | G25: Postponed to 5/3/2027 | H25: 22646.85 | I25: Bankruptcy history: 1 filing(s)
A26: 26APR25 | B26: MG-18-001363 | C26: 824 Arbordale Ln | D26: Marshall | E26: Postponed to 1/4/2027 | F26: excluded | G26: Postponed to 1/4/2027 | H26: 21512.1
A27: 114APR25 | B27: GD-24-002249 | C27: 4009 Outlook Dr | D27: West Mifflin | E27: Active | F27: excluded | G27: Docs outstanding: Court order (O/C) approving postponements covering 1 sale date(s): 11/2/26; Rule 3129.3 notice of postponed sale date (for 11/2/26) | H27: 27924.07
A28: 16MAY25 | B28: GD-23-009536 | C28: 6358 Lowell Drive | D28: Penn Hills | E28: Postponed to 1/4/2027 | F28: excluded | G28: Postponed to 1/4/2027 | H28: 44573.67 | I28: Bankruptcy history: 1 filing(s)
